<h1 id="asyncio-dev"> Develop with asyncio</h1> <p id="develop-with-asyncio">Asynchronous programming is different than classical “sequential” programming. This page lists common traps and explains how to avoid them.</p> <h2 id="asyncio-debug-mode">
<span class="section-number">18.5.9.1. </span>Debug mode of asyncio</h2> <p id="debug-mode-of-asyncio">The implementation of <a class="reference internal" href="asyncio#module-asyncio" title="asyncio: Asynchronous I/O, event loop, coroutines and tasks."><code>asyncio</code></a> has been written for performance. In order to ease the development of asynchronous code, you may wish to enable <em>debug mode</em>.</p> <p>To enable all debug checks for an application:</p> <ul class="simple"> <li>Enable the asyncio debug mode globally by setting the environment variable <code>PYTHONASYNCIODEBUG</code> to <code>1</code>, or by calling <a class="reference internal" href="asyncio-eventloop#asyncio.AbstractEventLoop.set_debug" title="asyncio.AbstractEventLoop.set_debug"><code>AbstractEventLoop.set_debug()</code></a>.</li> <li>Set the log level of the <a class="reference internal" href="#asyncio-logger"><span class="std std-ref">asyncio logger</span></a> to <code>logging.DEBUG</code>. For example, call <code>logging.basicConfig(level=logging.DEBUG)</code> at startup.</li> <li>Configure the <a class="reference internal" href="warnings#module-warnings" title="warnings: Issue warning messages and control their disposition."><code>warnings</code></a> module to display <a class="reference internal" href="exceptions#ResourceWarning" title="ResourceWarning"><code>ResourceWarning</code></a> warnings. For example, use the <code>-Wdefault</code> command line option of Python to display them.</li> </ul> <p>Examples debug checks:</p> <ul class="simple"> <li>Log <a class="reference internal" href="#asyncio-coroutine-not-scheduled"><span class="std std-ref">coroutines defined but never “yielded from”</span></a>
</li> <li>
<a class="reference internal" href="asyncio-eventloop#asyncio.AbstractEventLoop.call_soon" title="asyncio.AbstractEventLoop.call_soon"><code>call_soon()</code></a> and <a class="reference internal" href="asyncio-eventloop#asyncio.AbstractEventLoop.call_at" title="asyncio.AbstractEventLoop.call_at"><code>call_at()</code></a> methods raise an exception if they are called from the wrong thread.</li> <li>Log the execution time of the selector</li> <li>Log callbacks taking more than 100 ms to be executed. The <code>AbstractEventLoop.slow_callback_duration</code> attribute is the minimum duration in seconds of “slow” callbacks.</li> <li>
<a class="reference internal" href="exceptions#ResourceWarning" title="ResourceWarning"><code>ResourceWarning</code></a> warnings are emitted when transports and event loops are <a class="reference internal" href="#asyncio-close-transports"><span class="std std-ref">not closed explicitly</span></a>.</li> </ul> <div class="admonition seealso"> <p class="admonition-title">See also</p> <p>The <a class="reference internal" href="asyncio-eventloop#asyncio.AbstractEventLoop.set_debug" title="asyncio.AbstractEventLoop.set_debug"><code>AbstractEventLoop.set_debug()</code></a> method and the <a class="reference internal" href="#asyncio-logger"><span class="std std-ref">asyncio logger</span></a>.</p> </div> <h2 id="cancellation">
<span class="section-number">18.5.9.2. </span>Cancellation</h2> <p>Cancellation of tasks is not common in classic programming. In asynchronous programming, not only is it something common, but you have to prepare your code to handle it.</p> <p>Futures and tasks can be cancelled explicitly with their <a class="reference internal" href="asyncio-task#asyncio.Future.cancel" title="asyncio.Future.cancel"><code>Future.cancel()</code></a> method. The <a class="reference internal" href="asyncio-task#asyncio.wait_for" title="asyncio.wait_for"><code>wait_for()</code></a> function cancels the waited task when the timeout occurs. There are many other cases where a task can be cancelled indirectly.</p> <p>Don’t call <a class="reference internal" href="asyncio-task#asyncio.Future.set_result" title="asyncio.Future.set_result"><code>set_result()</code></a> or <a class="reference internal" href="asyncio-task#asyncio.Future.set_exception" title="asyncio.Future.set_exception"><code>set_exception()</code></a> method of <a class="reference internal" href="asyncio-task#asyncio.Future" title="asyncio.Future"><code>Future</code></a> if the future is cancelled: it would fail with an exception. For example, write:</p> <pre data-language="python">if not fut.cancelled():
    fut.set_result('done')
</pre> <p>Don’t schedule directly a call to the <a class="reference internal" href="asyncio-task#asyncio.Future.set_result" title="asyncio.Future.set_result"><code>set_result()</code></a> or the <a class="reference internal" href="asyncio-task#asyncio.Future.set_exception" title="asyncio.Future.set_exception"><code>set_exception()</code></a> method of a future with <a class="reference internal" href="asyncio-eventloop#asyncio.AbstractEventLoop.call_soon" title="asyncio.AbstractEventLoop.call_soon"><code>AbstractEventLoop.call_soon()</code></a>: the future can be cancelled before its method is called.</p> <p>If you wait for a future, you should check early if the future was cancelled to avoid useless operations. Example:</p> <pre data-language="python">@coroutine
def slow_operation(fut):
    if fut.cancelled():
        return
    # ... slow computation ...
    yield from fut
    # ...
</pre> <p>The <a class="reference internal" href="asyncio-task#asyncio.shield" title="asyncio.shield"><code>shield()</code></a> function can also be used to ignore cancellation.</p> <h2 id="asyncio-multithreading">
<span class="section-number">18.5.9.3. </span>Concurrency and multithreading</h2> <p id="concurrency-and-multithreading">An event loop runs in a thread and executes all callbacks and tasks in the same thread. While a task is running in the event loop, no other task is running in the same thread. But when the task uses <code>yield from</code>, the task is suspended and the event loop executes the next task.</p> <p>To schedule a callback from a different thread, the <a class="reference internal" href="asyncio-eventloop#asyncio.AbstractEventLoop.call_soon_threadsafe" title="asyncio.AbstractEventLoop.call_soon_threadsafe"><code>AbstractEventLoop.call_soon_threadsafe()</code></a> method should be used. Example:</p> <pre data-language="python">loop.call_soon_threadsafe(callback, *args)
</pre> <p>Most asyncio objects are not thread safe. You should only worry if you access objects outside the event loop. For example, to cancel a future, don’t call directly its <a class="reference internal" href="asyncio-task#asyncio.Future.cancel" title="asyncio.Future.cancel"><code>Future.cancel()</code></a> method, but:</p> <pre data-language="python">loop.call_soon_threadsafe(fut.cancel)
</pre> <p>To handle signals and to execute subprocesses, the event loop must be run in the main thread.</p> <p>To schedule a coroutine object from a different thread, the <a class="reference internal" href="asyncio-task#asyncio.run_coroutine_threadsafe" title="asyncio.run_coroutine_threadsafe"><code>run_coroutine_threadsafe()</code></a> function should be used. It returns a <a class="reference internal" href="concurrent.futures#concurrent.futures.Future" title="concurrent.futures.Future"><code>concurrent.futures.Future</code></a> to access the result:</p> <pre data-language="python">future = asyncio.run_coroutine_threadsafe(coro_func(), loop)
result = future.result(timeout)  # Wait for the result with a timeout
</pre> <p>The <a class="reference internal" href="asyncio-eventloop#asyncio.AbstractEventLoop.run_in_executor" title="asyncio.AbstractEventLoop.run_in_executor"><code>AbstractEventLoop.run_in_executor()</code></a> method can be used with a thread pool executor to execute a callback in different thread to not block the thread of the event loop.</p> <div class="admonition seealso"> <p class="admonition-title">See also</p> <p>The <a class="reference internal" href="asyncio-sync#asyncio-sync"><span class="std std-ref">Synchronization primitives</span></a> section describes ways to synchronize tasks.</p> <p>The <a class="reference internal" href="asyncio-subprocess#asyncio-subprocess-threads"><span class="std std-ref">Subprocess and threads</span></a> section lists asyncio limitations to run subprocesses from different threads.</p> </div> <h2 id="asyncio-handle-blocking">
<span class="section-number">18.5.9.4. </span>Handle blocking functions correctly</h2> <p id="handle-blocking-functions-correctly">Blocking functions should not be called directly. For example, if a function blocks for 1 second, other tasks are delayed by 1 second which can have an important impact on reactivity.</p> <p>For networking and subprocesses, the <a class="reference internal" href="asyncio#module-asyncio" title="asyncio: Asynchronous I/O, event loop, coroutines and tasks."><code>asyncio</code></a> module provides high-level APIs like <a class="reference internal" href="asyncio-protocol#asyncio-protocol"><span class="std std-ref">protocols</span></a>.</p> <p>An executor can be used to run a task in a different thread or even in a different process, to not block the thread of the event loop. See the <a class="reference internal" href="asyncio-eventloop#asyncio.AbstractEventLoop.run_in_executor" title="asyncio.AbstractEventLoop.run_in_executor"><code>AbstractEventLoop.run_in_executor()</code></a> method.</p> <div class="admonition seealso"> <p class="admonition-title">See also</p> <p>The <a class="reference internal" href="asyncio-eventloop#asyncio-delayed-calls"><span class="std std-ref">Delayed calls</span></a> section details how the event loop handles time.</p> </div> <h2 id="asyncio-logger">
<span class="section-number">18.5.9.5. </span>Logging</h2> <p id="logging">The <a class="reference internal" href="asyncio#module-asyncio" title="asyncio: Asynchronous I/O, event loop, coroutines and tasks."><code>asyncio</code></a> module logs information with the <a class="reference internal" href="logging#module-logging" title="logging: Flexible event logging system for applications."><code>logging</code></a> module in the logger <code>'asyncio'</code>.</p> <p>The default log level for the <a class="reference internal" href="asyncio#module-asyncio" title="asyncio: Asynchronous I/O, event loop, coroutines and tasks."><code>asyncio</code></a> module is <code>logging.INFO</code>. For those not wanting such verbosity from <a class="reference internal" href="asyncio#module-asyncio" title="asyncio: Asynchronous I/O, event loop, coroutines and tasks."><code>asyncio</code></a> the log level can be changed. For example, to change the level to <code>logging.WARNING</code>:</p> <pre data-language="none">logging.getLogger('asyncio').setLevel(logging.WARNING)
</pre> <h2 id="asyncio-coroutine-not-scheduled">
<span class="section-number">18.5.9.6. </span>Detect coroutine objects never scheduled</h2> <p id="detect-coroutine-objects-never-scheduled">When a coroutine function is called and its result is not passed to <a class="reference internal" href="asyncio-task#asyncio.ensure_future" title="asyncio.ensure_future"><code>ensure_future()</code></a> or to the <a class="reference internal" href="asyncio-eventloop#asyncio.AbstractEventLoop.create_task" title="asyncio.AbstractEventLoop.create_task"><code>AbstractEventLoop.create_task()</code></a> method, the execution of the coroutine object will never be scheduled which is probably a bug. <a class="reference internal" href="#asyncio-debug-mode"><span class="std std-ref">Enable the debug mode of asyncio</span></a> to <a class="reference internal" href="#asyncio-logger"><span class="std std-ref">log a warning</span></a> to detect it.</p> <p>Example with the bug:</p> <pre data-language="python">import asyncio

@asyncio.coroutine
def test():
    print("never scheduled")

test()
</pre> <p>Output in debug mode:</p> <pre data-language="python">Coroutine test() at test.py:3 was never yielded from
Coroutine object created at (most recent call last):
  File "test.py", line 7, in &lt;module&gt;
    test()
</pre> <p>The fix is to call the <a class="reference internal" href="asyncio-task#asyncio.ensure_future" title="asyncio.ensure_future"><code>ensure_future()</code></a> function or the <a class="reference internal" href="asyncio-eventloop#asyncio.AbstractEventLoop.create_task" title="asyncio.AbstractEventLoop.create_task"><code>AbstractEventLoop.create_task()</code></a> method with the coroutine object.</p> <div class="admonition seealso"> <p class="admonition-title">See also</p> <p><a class="reference internal" href="#asyncio-pending-task-destroyed"><span class="std std-ref">Pending task destroyed</span></a>.</p> </div> <h2 id="detect-exceptions-never-consumed">
<span class="section-number">18.5.9.7. </span>Detect exceptions never consumed</h2> <p>Python usually calls <a class="reference internal" href="sys#sys.excepthook" title="sys.excepthook"><code>sys.excepthook()</code></a> on unhandled exceptions. If <a class="reference internal" href="asyncio-task#asyncio.Future.set_exception" title="asyncio.Future.set_exception"><code>Future.set_exception()</code></a> is called, but the exception is never consumed, <a class="reference internal" href="sys#sys.excepthook" title="sys.excepthook"><code>sys.excepthook()</code></a> is not called. Instead, <a class="reference internal" href="#asyncio-logger"><span class="std std-ref">a log is emitted</span></a> when the future is deleted by the garbage collector, with the traceback where the exception was raised.</p> <p>Example of unhandled exception:</p> <pre data-language="python">import asyncio

@asyncio.coroutine
def bug():
    raise Exception("not consumed")

loop = asyncio.get_event_loop()
asyncio.ensure_future(bug())
loop.run_forever()
loop.close()
</pre> <p>Output:</p> <pre data-language="python">Task exception was never retrieved
future: &lt;Task finished coro=&lt;coro() done, defined at asyncio/coroutines.py:139&gt; exception=Exception('not consumed',)&gt;
Traceback (most recent call last):
  File "asyncio/tasks.py", line 237, in _step
    result = next(coro)
  File "asyncio/coroutines.py", line 141, in coro
    res = func(*args, **kw)
  File "test.py", line 5, in bug
    raise Exception("not consumed")
Exception: not consumed
</pre> <p><a class="reference internal" href="#asyncio-debug-mode"><span class="std std-ref">Enable the debug mode of asyncio</span></a> to get the traceback where the task was created. Output in debug mode:</p> <pre data-language="python">Task exception was never retrieved
future: &lt;Task finished coro=&lt;bug() done, defined at test.py:3&gt; exception=Exception('not consumed',) created at test.py:8&gt;
source_traceback: Object created at (most recent call last):
  File "test.py", line 8, in &lt;module&gt;
    asyncio.ensure_future(bug())
Traceback (most recent call last):
  File "asyncio/tasks.py", line 237, in _step
    result = next(coro)
  File "asyncio/coroutines.py", line 79, in __next__
    return next(self.gen)
  File "asyncio/coroutines.py", line 141, in coro
    res = func(*args, **kw)
  File "test.py", line 5, in bug
    raise Exception("not consumed")
Exception: not consumed
</pre> <p>There are different options to fix this issue. The first option is to chain the coroutine in another coroutine and use classic try/except:</p> <pre data-language="python">@asyncio.coroutine
def handle_exception():
    try:
        yield from bug()
    except Exception:
        print("exception consumed")

loop = asyncio.get_event_loop()
asyncio.ensure_future(handle_exception())
loop.run_forever()
loop.close()
</pre> <p>Another option is to use the <a class="reference internal" href="asyncio-eventloop#asyncio.AbstractEventLoop.run_until_complete" title="asyncio.AbstractEventLoop.run_until_complete"><code>AbstractEventLoop.run_until_complete()</code></a> function:</p> <pre data-language="python">task = asyncio.ensure_future(bug())
try:
    loop.run_until_complete(task)
except Exception:
    print("exception consumed")
</pre> <div class="admonition seealso"> <p class="admonition-title">See also</p> <p>The <a class="reference internal" href="asyncio-task#asyncio.Future.exception" title="asyncio.Future.exception"><code>Future.exception()</code></a> method.</p> </div> <h2 id="chain-coroutines-correctly">
<span class="section-number">18.5.9.8. </span>Chain coroutines correctly</h2> <p>When a coroutine function calls other coroutine functions and tasks, they should be chained explicitly with <code>yield from</code>. Otherwise, the execution is not guaranteed to be sequential.</p> <p>Example with different bugs using <a class="reference internal" href="asyncio-task#asyncio.sleep" title="asyncio.sleep"><code>asyncio.sleep()</code></a> to simulate slow operations:</p> <pre data-language="python">import asyncio

@asyncio.coroutine
def create():
    yield from asyncio.sleep(3.0)
    print("(1) create file")

@asyncio.coroutine
def write():
    yield from asyncio.sleep(1.0)
    print("(2) write into file")

@asyncio.coroutine
def close():
    print("(3) close file")

@asyncio.coroutine
def test():
    asyncio.ensure_future(create())
    asyncio.ensure_future(write())
    asyncio.ensure_future(close())
    yield from asyncio.sleep(2.0)
    loop.stop()

loop = asyncio.get_event_loop()
asyncio.ensure_future(test())
loop.run_forever()
print("Pending tasks at exit: %s" % asyncio.Task.all_tasks(loop))
loop.close()
</pre> <p>Expected output:</p> <pre data-language="none">(1) create file
(2) write into file
(3) close file
Pending tasks at exit: set()
</pre> <p>Actual output:</p> <pre data-language="none">(3) close file
(2) write into file
Pending tasks at exit: {&lt;Task pending create() at test.py:7 wait_for=&lt;Future pending cb=[Task._wakeup()]&gt;&gt;}
Task was destroyed but it is pending!
task: &lt;Task pending create() done at test.py:5 wait_for=&lt;Future pending cb=[Task._wakeup()]&gt;&gt;
</pre> <p>The loop stopped before the <code>create()</code> finished, <code>close()</code> has been called before <code>write()</code>, whereas coroutine functions were called in this order: <code>create()</code>, <code>write()</code>, <code>close()</code>.</p> <p>To fix the example, tasks must be marked with <code>yield from</code>:</p> <pre data-language="python">@asyncio.coroutine
def test():
    yield from asyncio.ensure_future(create())
    yield from asyncio.ensure_future(write())
    yield from asyncio.ensure_future(close())
    yield from asyncio.sleep(2.0)
    loop.stop()
</pre> <p>Or without <code>asyncio.ensure_future()</code>:</p> <pre data-language="python">@asyncio.coroutine
def test():
    yield from create()
    yield from write()
    yield from close()
    yield from asyncio.sleep(2.0)
    loop.stop()
</pre> <h2 id="asyncio-pending-task-destroyed">
<span class="section-number">18.5.9.9. </span>Pending task destroyed</h2> <p id="pending-task-destroyed">If a pending task is destroyed, the execution of its wrapped <a class="reference internal" href="asyncio-task#coroutine"><span class="std std-ref">coroutine</span></a> did not complete. It is probably a bug and so a warning is logged.</p> <p>Example of log:</p> <pre data-language="none">Task was destroyed but it is pending!
task: &lt;Task pending coro=&lt;kill_me() done, defined at test.py:5&gt; wait_for=&lt;Future pending cb=[Task._wakeup()]&gt;&gt;
</pre> <p><a class="reference internal" href="#asyncio-debug-mode"><span class="std std-ref">Enable the debug mode of asyncio</span></a> to get the traceback where the task was created. Example of log in debug mode:</p> <pre data-language="none">Task was destroyed but it is pending!
source_traceback: Object created at (most recent call last):
  File "test.py", line 15, in &lt;module&gt;
    task = asyncio.ensure_future(coro, loop=loop)
task: &lt;Task pending coro=&lt;kill_me() done, defined at test.py:5&gt; wait_for=&lt;Future pending cb=[Task._wakeup()] created at test.py:7&gt; created at test.py:15&gt;
</pre> <div class="admonition seealso"> <p class="admonition-title">See also</p> <p><a class="reference internal" href="#asyncio-coroutine-not-scheduled"><span class="std std-ref">Detect coroutine objects never scheduled</span></a>.</p> </div> <h2 id="asyncio-close-transports">
<span class="section-number">18.5.9.10. </span>Close transports and event loops</h2> <p id="close-transports-and-event-loops">When a transport is no more needed, call its <code>close()</code> method to release resources. Event loops must also be closed explicitly.</p> <p>If a transport or an event loop is not closed explicitly, a <a class="reference internal" href="exceptions#ResourceWarning" title="ResourceWarning"><code>ResourceWarning</code></a> warning will be emitted in its destructor. By default, <a class="reference internal" href="exceptions#ResourceWarning" title="ResourceWarning"><code>ResourceWarning</code></a> warnings are ignored. The <a class="reference internal" href="#asyncio-debug-mode"><span class="std std-ref">Debug mode of asyncio</span></a> section explains how to display them.</p><div class="_attribution">
<p class="_attribution-p">
    © 2001–2020 Python Software Foundation<br/>Licensed under the PSF License.<br/>
https://docs.python.org/3.6/library/asyncio-dev.html
</p>
</div>
